Workbook

Sheet S3 Concern summary
A2: STAGE 3 CONCERN MOVEMENT DASHBOARD
A3: ZONE & REGION | B3: OPENING & ADDITIONAL | E3: AS ON DATE FLOW | H3: 46143 | J3: FTD | K3: Direct Flow | N3: 30-59 DPD Flow | Q3: Existing Stock | T3: RB From NPA
B4: Stock | C4: Collected | D4: Res % | E4: Flow | F4: CLNPA | G4: Total | H4: LMTD% | I4: LMTD FLOW | K4: STOCK | L4: COLL | M4: EFF | N4: STOCK | O4: COLL | P4: EFF | Q4: STOCK | R4: COLL | S4: EFF | T4: STOCK | U4: COLL | V4: EFF
A5: PAN INDIA | B5: 398.71142 | C5: 111.14243 | D5: 0.27875406 | E5: 290.35865 | F5: 28.946237 | G5: 319.30489 | H5: 0.28162733 | I5: 266.60587 | J5: 7.9053357 | K5: 33.465108 | L5: 3.3723801 | M5: 0.10077302 | N5: 82.282455 | O5: 34.674831 | P5: 0.42141221 | Q5: 256.71722 | R5: 65.494589 | S5: 0.25512347 | T5: 26.246637 | U5: 7.6006272 | V5: 0.2895848
A6: EAST | B6: 42.350998 | C6: 9.9095364 | D6: 0.2339859 | E6: 32.775076 | F6: 4.8448097 | G6: 37.619885 | H6: 0.31637951 | I6: 28.339715 | J6: 0 | K6: 3.0999281 | L6: 0.63173775 | M6: 0.2037911 | N6: 8.3922073 | O6: 2.6370717 | P6: 0.31422862 | Q6: 27.471222 | R6: 5.2185684 | S6: 0.18996491 | T6: 3.3876399 | U6: 1.4221586 | V6: 0.41980808
A7: EAST_1 | B7: 21.492982 | C7: 1.5542366 | D7: 0.07231368 | E7: 20.123655 | F7: 4.584875 | G7: 24.70853 | H7: 0.28859515 | I7: 16.979391 | J7: 0 | K7: 2.3042412 | L7: 0.1245281 | M7: 0.054042997 | N7: 3.0770691 | O7: 0.3551845 | P7: 0.11542948 | Q7: 15.196451 | R7: 0.338955 | S7: 0.022304879 | T7: 0.9152202 | U7: 0.735569 | V7: 0.80370713
A8: CHATTISGARH | B8: 6.751043 | C8: 0.6016893 | D8: 0.089125385 | E8: 6.2138956 | F8: 4.296518 | G8: 10.510414 | H8: 0.17731837 | I8: 4.8206256 | J8: 0 | K8: 0.43965566 | L8: 0 | M8: 0 | N8: 1.9725043 | O8: 0.3551845 | P8: 0.1800678 | Q8: 4.338883 | R8: 0.2465048 | S8: 0.056812963 | T8: 0 | U8: 0 | V8: -
A9: CHATTISGARH_1 | B9: 5.3351884 | C9: 0 | D9: 0 | E9: 5.3894773 | F9: 4.296518 | G9: 9.6859953 | H9: 0.18802331 | I9: 3.4112258 | J9: 0 | K9: 0.43965566 | L9: 0 | M9: 0 | N9: 1.5785111 | O9: 0 | P9: 0 | Q9: 3.3170216 | R9: 0 | S9: 0 | T9: 0 | U9: 0 | V9: -
A10: BHILAI_AREA | B10: 3.8387558 | C10: 0 | D10: 0 | E10: 3.877308 | F10: 0 | G10: 3.877308 | H10: 0 | I10: 2.7899693 | J10: 0 | K10: 0.4086493 | L10: 0 | M10: 0 | N10: 0.6707366 | O10: 0 | P10: 0 | Q10: 2.7593699 | R10: 0 | S10: 0 | T10: 0 | U10: 0 | V10: -
A11: JAGDALPUR_AREA | B11: 0 | C11: 0 | D11: - | E11: 0 | F11: 0 | G11: 0 | H11: 0 | I11: 0 | J11: 0 | K11: 0 | L11: 0 | M11: - | N11: 0 | O11: 0 | P11: - | Q11: 0 | R11: 0 | S11: - | T11: 0 | U11: 0 | V11: -
A12: RAIPUR_1_AREA | B12: 1.4964326 | C12: 0 | D12: 0 | E12: 1.5121694 | F12: 4.296518 | G12: 5.8086874 | H12: 0.55997052 | I12: 0.62125656 | J12: 0 | K12: 0.031006359 | L12: 0 | M12: 0 | N12: 0.90777452 | O12: 0 | P12: 0 | Q12: 0.55765173 | R12: 0 | S12: 0 | T12: 0 | U12: 0 | V12: -
A13: RAIPUR_2_AREA | B13: 0 | C13: 0 | D13: - | E13: 0 | F13: 0 | G13: 0 | H13: 0 | I13: 0 | J13: 0 | K13: 0 | L13: 0 | M13: - | N13: 0 | O13: 0 | P13: - | Q13: 0 | R13: 0 | S13: - | T13: 0 | U13: 0 | V13: -
A14: SARAIPALI_AREA | B14: 0 | C14: 0 | D14: - | E14: 0 | F14: 0 | G14: 0 | H14: 0 | I14: 0 | J14: 0 | K14: 0 | L14: 0 | M14: - | N14: 0 | O14: 0 | P14: - | Q14: 0 | R14: 0 | S14: - | T14: 0 | U14: 0 | V14: -
A15: CHATTISGARH_2 | B15: 1.4158546 | C15: 0.6016893 | D15: 0.42496547 | E15: 0.82441821 | F15: 0 | G15: 0.82441821 | H15: 0.15011017 | I15: 1.4093998 | J15: 0 | K15: 0 | L15: 0 | M15: - | N15: 0.39399317 | O15: 0.3551845 | P15: 0.90149913 | Q15: 1.0218614 | R15: 0.2465048 | S15: 0.24123115 | T15: 0 | U15: 0 | V15: -
A16: AMBIKAPUR_AREA | B16: 0 | C16: 0 | D16: - | E16: 0 | F16: 0 | G16: 0 | H16: 0 | I16: 0 | J16: 0 | K16: 0 | L16: 0 | M16: - | N16: 0 | O16: 0 | P16: - | Q16: 0 | R16: 0 | S16: - | T16: 0 | U16: 0 | V16: -
A17: BILASPUR_AREA | B17: 0.1835567 | C17: 0 | D17: 0 | E17: 0.1863875 | F17: 0 | G17: 0.1863875 | H17: 0 | I17: 0.51908335 | J17: 0 | K17: 0 | L17: 0 | M17: - | N17: 0 | O17: 0 | P17: - | Q17: 0.1835567 | R17: 0 | S17: 0 | T17: 0 | U17: 0 | V17: -
A18: RAIGARH_AREA | B18: 1.2322979 | C18: 0.6016893 | D18: 0.48826612 | E18: 0.63803071 | F18: 0 | G18: 0.63803071 | H18: 0.21840872 | I18: 0.89031645 | J18: 0 | K18: 0 | L18: 0 | M18: - | N18: 0.39399317 | O18: 0.3551845 | P18: 0.90149913 | Q18: 0.8383047 | R18: 0.2465048 | S18: 0.29405155 | T18: 0 | U18: 0 | V18: -
A19: CHATTISGARH_3 | B19: 0 | C19: 0 | D19: - | E19: 0 | F19: 0 | G19: 0 | H19: 0 | I19: 0 | J19: 0 | K19: 0 | L19: 0 | M19: - | N19: 0 | O19: 0 | P19: - | Q19: 0 | R19: 0 | S19: - | T19: 0 | U19: 0 | V19: -
A20: RAIPUR_3_AREA | B20: 0 | C20: 0 | D20: - | E20: 0 | F20: 0 | G20: 0 | H20: 0 | I20: 0 | J20: 0 | K20: 0 | L20: 0 | M20: - | N20: 0 | O20: 0 | P20: - | Q20: 0 | R20: 0 | S20: - | T20: 0 | U20: 0 | V20: -
A21: ODISHA | B21: 3.4322389 | C21: 0.8280192 | D21: 0.24124754 | E21: 2.6352455 | F21: 0.1670447 | G21: 2.8022902 | H21: 0.19256979 | I21: 2.0447621 | J21: 0 | K21: 1.5031018 | L21: 0 | M21: 0 | N21: 0.4685982 | O21: 0 | P21: 0 | Q21: 0.5453187 | R21: 0.0924502 | S21: 0.16953426 | T21: 0.9152202 | U21: 0.735569 | V21: 0.80370713
A22: ODISHA_REGION | B22: 3.4322389 | C22: 0.8280192 | D22: 0.24124754 | E22: 2.6352455 | F22: 0.1670447 | G22: 2.8022902 | H22: 0.19256979 | I22: 2.0447621 | J22: 0 | K22: 1.5031018 | L22: 0 | M22: 0 | N22: 0.4685982 | O22: 0 | P22: 0 | Q22: 0.5453187 | R22: 0.0924502 | S22: 0.16953426 | T22: 0.9152202 | U22: 0.735569 | V22: 0.80370713
A23: BHUBANESWAR_AREA | B23: 1.0707734 | C23: 0.735569 | D23: 0.68695113 | E23: 0.339649 | F23: 0.0079314 | G23: 0.3475804 | H23: 0 | I23: 0.46422017 | J23: 0 | K23: 0 | L23: 0 | M23: - | N23: 0.1347883 | O23: 0 | P23: 0 | Q23: 0.2004161 | R23: 0 | S23: 0 | T23: 0.735569 | U23: 0.735569 | V23: 1
A24: CUTTACK_AREA | B24: 2.2379413 | C24: 0.0924502 | D24: 0.041310378 | E24: 2.1703396 | F24: 0.0990929 | G24: 2.2694325 | H24: 0.37940735 | I24: 0.79843241 | J24: 0 | K24: 1.5031018 | L24: 0 | M24: 0 | N24: 0.2102857 | O24: 0 | P24: 0 | Q24: 0.3449026 | R24: 0.0924502 | S24: 0.26804727 | T24: 0.1796512 | U24: 0 | V24: 0
A25: ORISSA_BEHRAMPUR_AREA | B25: 0 | C25: 0 | D25: - | E25: 0 | F25: 0 | G25: 0 | H25: 0 | I25: 0 | J25: 0 | K25: 0 | L25: 0 | M25: - | N25: 0 | O25: 0 | P25: - | Q25: 0 | R25: 0 | S25: - | T25: 0 | U25: 0 | V25: -
A26: SAMBALPUR_AREA | B26: 0.1235242 | C26: 0 | D26: 0 | E26: 0.1252569 | F26: 0.0600204 | G26: 0.1852773 | H26: 0 | I26: 0.78210951 | J26: 0 | K26: 0 | L26: 0 | M26: - | N26: 0.1235242 | O26: 0 | P26: 0 | Q26: 0 | R26: 0 | S26: - | T26: 0 | U26: 0 | V26: -
A27: WEST_BENGAL | B27: 11.3097 | C27: 0.1245281 | D27: 0.011010734 | E27: 11.274514 | F27: 0.12131227 | G27: 11.395826 | H27: 0.3464815 | I27: 10.114003 | J27: 0 | K27: 0.36148374 | L27: 0.1245281 | M27: 0.34449156 | N27: 0.63596663 | O27: 0 | P27: 0 | Q27: 10.31225 | R27: 0 | S27: 0 | T27: 0 | U27: 0 | V27: -
A28: WB_REGION | B28: 11.3097 | C28: 0.1245281 | D28: 0.011010734 | E28: 11.274514 | F28: 0.12131227 | G28: 11.395826 | H28: 0.3464815 | I28: 10.114003 | J28: 0 | K28: 0.36148374 | L28: 0.1245281 | M28: 0.34449156 | N28: 0.63596663 | O28: 0 | P28: 0 | Q28: 10.31225 | R28: 0 | S28: 0 | T28: 0 | U28: 0 | V28: -
A29: BARASAT_AREA | B29: 1.4389166 | C29: 0 | D29: 0 | E29: 1.4584076 | F29: 0.0098395 | G29: 1.4682471 | H29: 0 | I29: 1.6600815 | J29: 0 | K29: 0.2030698 | L29: 0 | M29: 0 | N29: 0.1493633 | O29: 0 | P29: 0 | Q29: 1.0864835 | R29: 0 | S29: 0 | T29: 0 | U29: 0 | V29: -
A30: DURGAPUR_AREA | B30: 3.4955735 | C30: 0 | D30: 0 | E30: 3.5360957 | F30: 0.01782227 | G30: 3.553918 | H30: 0.11951837 | I30: 3.5975453 | J30: 0 | K30: 0 | L30: 0 | M30: - | N30: 0.0612986 | O30: 0 | P30: 0 | Q30: 3.4342749 | R30: 0 | S30: 0 | T30: 0 | U30: 0 | V30: -
A31: KHARAGPUR_AREA | B31: 0 | C31: 0 | D31: - | E31: 0 | F31: 0 | G31: 0 | H31: 1 | I31: 0 | J31: 0 | K31: 0 | L31: 0 | M31: - | N31: 0 | O31: 0 | P31: - | Q31: 0 | R31: 0 | S31: - | T31: 0 | U31: 0 | V31: -
A32: KOLKATA_AREA | B32: 5.7212025 | C32: 0 | D32: 0 | E32: 5.7460077 | F32: 0.0868442 | G32: 5.8328519 | H32: 0.45551474 | I32: 4.7945178 | J32: 0 | K32: 0.033885842 | L32: 0 | M32: 0 | N32: 0.24834123 | O32: 0 | P32: 0 | Q32: 5.4389754 | R32: 0 | S32: 0 | T32: 0 | U32: 0 | V32: -
A33: KRISHNA_NAGAR_AREA | B33: 0 | C33: 0 | D33: - | E33: 0 | F33: 0 | G33: 0 | H33: 0 | I33: 0 | J33: 0 | K33: 0 | L33: 0 | M33: - | N33: 0 | O33: 0 | P33: - | Q33: 0 | R33: 0 | S33: - | T33: 0 | U33: 0 | V33: -
A34: SILIGURI_AREA | B34: 0.65400741 | C34: 0.1245281 | D34: 0.19040778 | E34: 0.5340028 | F34: 0.0068063 | G34: 0.5408091 | H34: 0.82727159 | I34: 0.061858396 | J34: 0 | K34: 0.1245281 | L34: 0.1245281 | M34: 1 | N34: 0.1769635 | O34: 0 | P34: 0 | Q34: 0.35251581 | R34: 0 | S34: 0 | T34: 0 | U34: 0 | V34: -
A35: EAST_2 | B35: 20.858016 | C35: 8.3552998 | D35: 0.4005798 | E35: 12.651421 | F35: 0.2599347 | G35: 12.911355 | H35: 0.35408007 | I35: 11.360325 | J35: 0 | K35: 0.79568695 | L35: 0.50720965 | M35: 0.63744875 | N35: 5.3151382 | O35: 2.2818872 | P35: 0.42931851 | Q35: 12.274771 | R35: 4.8796134 | S35: 0.39753193 | T35: 2.4724197 | U35: 0.6865896 | V35: 0.27769945
A36: BIHAR | B36: 4.5475976 | C36: 0.96801565 | D36: 0.21286308 | E36: 3.6229589 | F36: 0.0944021 | G36: 3.717361 | H36: 0.44692372 | I36: 2.2247941 | J36: 0 | K36: 0.25516345 | L36: 0.08577955 | M36: 0.33617491 | N36: 2.0338738 | O36: 0 | P36: 0 | Q36: 2.1103186 | R36: 0.8822361 | S36: 0.41805824 | T36: 0.1482417 | U36: 0 | V36: 0
A37: BIHAR_REGION | B37: 4.5475976 | C37: 0.96801565 | D37: 0.21286308 | E37: 3.6229589 | F37: 0.0944021 | G37: 3.717361 | H37: 0.44692372 | I37: 2.2247941 | J37: 0 | K37: 0.25516345 | L37: 0.08577955 | M37: 0.33617491 | N37: 2.0338738 | O37: 0 | P37: 0 | Q37: 2.1103186 | R37: 0.8822361 | S37: 0.41805824 | T37: 0.1482417 | U37: 0 | V37: 0
A38: HAJIPUR_AREA | B38: 1.8160148 | C38: 0.4963359 | D38: 0.27331049 | E38: 1.3371726 | F38: 0.0467329 | G38: 1.3839055 | H38: 0.49038821 | I38: 0.93336218 | J38: 0 | K38: 0.1693839 | L38: 0 | M38: 0 | N38: 0.3008404 | O38: 0 | P38: 0 | Q38: 1.1975488 | R38: 0.4963359 | S38: 0.41445985 | T38: 0.1482417 | U38: 0 | V38: 0
A39: MUZAFFARPUR_AREA | B39: 0.29009525 | C39: 0.1346386 | D39: 0.4641186 | E39: 0.1577317 | F39: 0.0315913 | G39: 0.189323 | H39: 0.49156868 | I39: 0.14226475 | J39: 0 | K39: 0 | L39: 0 | M39: - | N39: 0.0977655 | O39: 0 | P39: 0 | Q39: 0.19232975 | R39: 0.1346386 | S39: 0.70004044 | T39: 0 | U39: 0 | V39: -
A40: PATNA_AREA | B40: 2.0597055 | C40: 0.2512616 | D40: 0.12198909 | E40: 1.8279863 | F40: 0 | G40: 1.8279863 | H40: 0.3907415 | I40: 0.82538492 | J40: 0 | K40: 0 | L40: 0 | M40: - | N40: 1.6352679 | O40: 0 | P40: 0 | Q40: 0.4244376 | R40: 0.2512616 | S40: 0.59198714 | T40: 0 | U40: 0 | V40: -
A41: PURNEA_AREA | B41: 0.38178205 | C41: 0.08577955 | D41: 0.22468199 | E41: 0.3000683 | F41: 0.0160779 | G41: 0.3161462 | H41: 0.41854271 | I41: 0.32378228 | J41: 0 | K41: 0.08577955 | L41: 0.08577955 | M41: 1 | N41: 0 | O41: 0 | P41: - | Q41: 0.2960025 | R41: 0 | S41: 0 | T41: 0 | U41: 0 | V41: -
...

Sheet New Summary
C2: PAN INDIA - MLAP COLLECTION SCORECARD - JAN-00
B4: ZONE & REGION | C4: Opening Stock | F4: Flow | I4: 46143 | K4: FTD | L4: Direct Flow | O4: 30-59 DPD Flow | R4: Existing Stock | U4: RB From NPA
C5: Stock | D5: Collection | E5: Res % | F5: Flow | G5: CLNPA | H5: Total | I5: LMTD % | J5: LMTD Flow | L5: Stock | M5: Coll | N5: Res % | O5: Stock | P5: Coll | Q5: Res % | R5: Stock | S5: Coll | T5: Res % | U5: Stock | V5: Coll | W5: Res %
B6: ='S3 Concern summary'!A5 -> PAN INDIA | C6: ='S3 Concern summary'!B5 -> 398.71142 | D6: ='S3 Concern summary'!C5 -> 111.14243 | E6: ='S3 Concern summary'!D5 -> 0.27875406 | F6: ='S3 Concern summary'!E5 -> 290.35865 | G6: ='S3 Concern summary'!F5 -> 28.946237 | H6: ='S3 Concern summary'!G5 -> 319.30489 | I6: ='S3 Concern summary'!H5 -> 0.28162733 | ... W6: ='S3 Concern summary'!V5 -> 0.2895848
B7: ='S3 Concern summary'!A6 -> EAST | C7: ='S3 Concern summary'!B6 -> 42.350998 | D7: ='S3 Concern summary'!C6 -> 9.9095364 | E7: ='S3 Concern summary'!D6 -> 0.2339859 | F7: ='S3 Concern summary'!E6 -> 32.775076 | G7: ='S3 Concern summary'!F6 -> 4.8448097 | H7: ='S3 Concern summary'!G6 -> 37.619885 | I7: ='S3 Concern summary'!H6 -> 0.31637951 | ... W7: ='S3 Concern summary'!V6 -> 0.41980808
B8: ='S3 Concern summary'!A7 -> EAST_1 | C8: ='S3 Concern summary'!B7 -> 21.492982 | D8: ='S3 Concern summary'!C7 -> 1.5542366 | E8: ='S3 Concern summary'!D7 -> 0.07231368 | F8: ='S3 Concern summary'!E7 -> 20.123655 | G8: ='S3 Concern summary'!F7 -> 4.584875 | H8: ='S3 Concern summary'!G7 -> 24.70853 | I8: ='S3 Concern summary'!H7 -> 0.28859515 | ... W8: ='S3 Concern summary'!V7 -> 0.80370713
B9: ='S3 Concern summary'!A8 -> CHATTISGARH | C9: ='S3 Concern summary'!B8 -> 6.751043 | D9: ='S3 Concern summary'!C8 -> 0.6016893 | E9: ='S3 Concern summary'!D8 -> 0.089125385 | F9: ='S3 Concern summary'!E8 -> 6.2138956 | G9: ='S3 Concern summary'!F8 -> 4.296518 | H9: ='S3 Concern summary'!G8 -> 10.510414 | I9: ='S3 Concern summary'!H8 -> 0.17731837 | ... W9: ='S3 Concern summary'!V8 -> -
B10: ='S3 Concern summary'!A21 -> ODISHA | C10: ='S3 Concern summary'!B21 -> 3.4322389 | D10: ='S3 Concern summary'!C21 -> 0.8280192 | E10: ='S3 Concern summary'!D21 -> 0.24124754 | F10: ='S3 Concern summary'!E21 -> 2.6352455 | G10: ='S3 Concern summary'!F21 -> 0.1670447 | H10: ='S3 Concern summary'!G21 -> 2.8022902 | I10: ='S3 Concern summary'!H21 -> 0.19256979 | ... W10: ='S3 Concern summary'!V21 -> 0.80370713
B11: ='S3 Concern summary'!A27 -> WEST_BENGAL | C11: ='S3 Concern summary'!B27 -> 11.3097 | D11: ='S3 Concern summary'!C27 -> 0.1245281 | E11: ='S3 Concern summary'!D27 -> 0.011010734 | F11: ='S3 Concern summary'!E27 -> 11.274514 | G11: ='S3 Concern summary'!F27 -> 0.12131227 | H11: ='S3 Concern summary'!G27 -> 11.395826 | I11: ='S3 Concern summary'!H27 -> 0.3464815 | ... W11: ='S3 Concern summary'!V27 -> -
B12: ='S3 Concern summary'!A35 -> EAST_2 | C12: ='S3 Concern summary'!B35 -> 20.858016 | D12: ='S3 Concern summary'!C35 -> 8.3552998 | E12: ='S3 Concern summary'!D35 -> 0.4005798 | F12: ='S3 Concern summary'!E35 -> 12.651421 | G12: ='S3 Concern summary'!F35 -> 0.2599347 | H12: ='S3 Concern summary'!G35 -> 12.911355 | I12: ='S3 Concern summary'!H35 -> 0.35408007 | ... W12: ='S3 Concern summary'!V35 -> 0.27769945
B13: ='S3 Concern summary'!A36 -> BIHAR | C13: ='S3 Concern summary'!B36 -> 4.5475976 | D13: ='S3 Concern summary'!C36 -> 0.96801565 | E13: ='S3 Concern summary'!D36 -> 0.21286308 | F13: ='S3 Concern summary'!E36 -> 3.6229589 | G13: ='S3 Concern summary'!F36 -> 0.0944021 | H13: ='S3 Concern summary'!G36 -> 3.717361 | I13: ='S3 Concern summary'!H36 -> 0.44692372 | ... W13: ='S3 Concern summary'!V36 -> 0
B14: ='S3 Concern summary'!A42 -> JHARKHAND | C14: ='S3 Concern summary'!B42 -> 2.1448789 | D14: ='S3 Concern summary'!C42 -> 0.8148059 | E14: ='S3 Concern summary'!D42 -> 0.37988434 | F14: ='S3 Concern summary'!E42 -> 1.345697 | G14: ='S3 Concern summary'!F42 -> 0.0557899 | H14: ='S3 Concern summary'!G42 -> 1.4014869 | I14: ='S3 Concern summary'!H42 -> 0.2807493 | ... W14: ='S3 Concern summary'!V42 -> -
B15: ='S3 Concern summary'!A45 -> NORTH_EAST | C15: ='S3 Concern summary'!B45 -> 14.165539 | D15: ='S3 Concern summary'!C45 -> 6.5724783 | E15: ='S3 Concern summary'!D45 -> 0.46397656 | F15: ='S3 Concern summary'!E45 -> 7.6827649 | G15: ='S3 Concern summary'!F45 -> 0.1097427 | H15: ='S3 Concern summary'!G45 -> 7.7925076 | I15: ='S3 Concern summary'!H45 -> 0.33911392 | ... W15: ='S3 Concern summary'!V45 -> 0.2954118
B16: ='S3 Concern summary'!A51 -> NORTH | C16: ='S3 Concern summary'!B51 -> 134.698 | D16: ='S3 Concern summary'!C51 -> 32.847484 | E16: ='S3 Concern summary'!D51 -> 0.24386022 | F16: ='S3 Concern summary'!E51 -> 103.03681 | G16: ='S3 Concern summary'!F51 -> 11.920554 | H16: ='S3 Concern summary'!G51 -> 114.95737 | I16: ='S3 Concern summary'!H51 -> 0.22686256 | ... W16: ='S3 Concern summary'!V51 -> 0.27486613
B17: ='S3 Concern summary'!A52 -> NORTH_1 | C17: ='S3 Concern summary'!B52 -> 53.568997 | D17: ='S3 Concern summary'!C52 -> 17.496308 | E17: ='S3 Concern summary'!D52 -> 0.32661257 | F17: ='S3 Concern summary'!E52 -> 36.514232 | G17: ='S3 Concern summary'!F52 -> 3.2447366 | H17: ='S3 Concern summary'!G52 -> 39.758969 | I17: ='S3 Concern summary'!H52 -> 0.32336586 | ... W17: ='S3 Concern summary'!V52 -> 0.92178176
B18: ='S3 Concern summary'!A53 -> DELHI | C18: ='S3 Concern summary'!B53 -> 49.39688 | D18: ='S3 Concern summary'!C53 -> 15.227049 | E18: ='S3 Concern summary'!D53 -> 0.30825934 | F18: ='S3 Concern summary'!E53 -> 34.584197 | G18: ='S3 Concern summary'!F53 -> 2.2275902 | H18: ='S3 Concern summary'!G53 -> 36.811787 | I18: ='S3 Concern summary'!H53 -> 0.32917455 | ... W18: ='S3 Concern summary'!V53 -> 0.98040559
B19: ='S3 Concern summary'!A90 -> UTTAR_PRADESH | C19: ='S3 Concern summary'!B90 -> 4.1721173 | D19: ='S3 Concern summary'!C90 -> 2.2692585 | E19: ='S3 Concern summary'!D90 -> 0.54391052 | F19: ='S3 Concern summary'!E90 -> 1.9300353 | G19: ='S3 Concern summary'!F90 -> 1.0171464 | H19: ='S3 Concern summary'!G90 -> 2.9471817 | I19: ='S3 Concern summary'!H90 -> 0.24248599 | ... W19: ='S3 Concern summary'!V90 -> 0.90039636
B20: ='S3 Concern summary'!A100 -> NORTH_2 | C20: ='S3 Concern summary'!B100 -> 32.77168 | D20: ='S3 Concern summary'!C100 -> 9.5458808 | E20: ='S3 Concern summary'!D100 -> 0.29128445 | F20: ='S3 Concern summary'!E100 -> 23.483689 | G20: ='S3 Concern summary'!F100 -> 5.0632371 | H20: ='S3 Concern summary'!G100 -> 28.546926 | I20: ='S3 Concern summary'!H100 -> 0.13892678 | ... W20: ='S3 Concern summary'!V100 -> 0.040933654
B21: ='S3 Concern summary'!A101 -> PHC | C21: ='S3 Concern summary'!B101 -> 18.467127 | D21: ='S3 Concern summary'!C101 -> 3.8471033 | E21: ='S3 Concern summary'!D101 -> 0.2083217 | F21: ='S3 Concern summary'!E101 -> 14.781929 | G21: ='S3 Concern summary'!F101 -> 0.2800762 | H21: ='S3 Concern summary'!G101 -> 15.062005 | I21: ='S3 Concern summary'!H101 -> 0.13391656 | ... W21: ='S3 Concern summary'!V101 -> 1
B22: ='S3 Concern summary'!A120 -> UTTARAKHAND | C22: ='S3 Concern summary'!B120 -> 14.304552 | D22: ='S3 Concern summary'!C120 -> 5.6987775 | E22: ='S3 Concern summary'!D120 -> 0.39838908 | F22: ='S3 Concern summary'!E120 -> 8.7017603 | G22: ='S3 Concern summary'!F120 -> 4.7831609 | H22: ='S3 Concern summary'!G120 -> 13.484921 | I22: ='S3 Concern summary'!H120 -> 0.15532692 | ... W22: ='S3 Concern summary'!V120 -> 0
B23: ='S3 Concern summary'!A125 -> NORTH_3 | C23: ='S3 Concern summary'!B125 -> 48.357321 | D23: ='S3 Concern summary'!C125 -> 5.8052949 | E23: ='S3 Concern summary'!D125 -> 0.12004997 | F23: ='S3 Concern summary'!E125 -> 43.038893 | G23: ='S3 Concern summary'!F125 -> 3.6125802 | H23: ='S3 Concern summary'!G125 -> 46.651473 | I23: ='S3 Concern summary'!H125 -> 0.15042106 | ... W23: ='S3 Concern summary'!V125 -> 0.10792411
B24: ='S3 Concern summary'!A126 -> RAJASTHAN_1 | C24: ='S3 Concern summary'!B126 -> 23.086097 | D24: ='S3 Concern summary'!C126 -> 2.4986804 | E24: ='S3 Concern summary'!D126 -> 0.10823312 | F24: ='S3 Concern summary'!E126 -> 20.826867 | G24: ='S3 Concern summary'!F126 -> 0.8232784 | H24: ='S3 Concern summary'!G126 -> 21.650146 | I24: ='S3 Concern summary'!H126 -> 0.1173319 | ... W24: ='S3 Concern summary'!V126 -> 0
B25: ='S3 Concern summary'!A141 -> RAJASTHAN_2 | C25: ='S3 Concern summary'!B141 -> 25.271224 | D25: ='S3 Concern summary'!C141 -> 3.3066145 | E25: ='S3 Concern summary'!D141 -> 0.13084505 | F25: ='S3 Concern summary'!E141 -> 22.212026 | G25: ='S3 Concern summary'!F141 -> 2.7893018 | H25: ='S3 Concern summary'!G141 -> 25.001328 | I25: ='S3 Concern summary'!H141 -> 0.17921823 | ... W25: ='S3 Concern summary'!V141 -> 0.11263391
B26: ='S3 Concern summary'!A152 -> SOUTH | C26: ='S3 Concern summary'!B152 -> 168.70785 | D26: ='S3 Concern summary'!C152 -> 44.851742 | E26: ='S3 Concern summary'!D152 -> 0.26585451 | F26: ='S3 Concern summary'!E152 -> 125.16664 | G26: ='S3 Concern summary'!F152 -> 8.9214302 | H26: ='S3 Concern summary'!G152 -> 134.08807 | I26: ='S3 Concern summary'!H152 -> 0.31325988 | ... W26: ='S3 Concern summary'!V152 -> 0.19203147
B27: ='S3 Concern summary'!A153 -> SOUTH_1 | C27: ='S3 Concern summary'!B153 -> 97.742274 | D27: ='S3 Concern summary'!C153 -> 20.839795 | E27: ='S3 Concern summary'!D153 -> 0.21321169 | F27: ='S3 Concern summary'!E153 -> 77.650568 | G27: ='S3 Concern summary'!F153 -> 6.2858019 | H27: ='S3 Concern summary'!G153 -> 83.93637 | I27: ='S3 Concern summary'!H153 -> 0.29122698 | ... W27: ='S3 Concern summary'!V153 -> 0.19477057
B28: ='S3 Concern summary'!A154 -> ANDHRA_PRADESH | C28: ='S3 Concern summary'!B154 -> 34.098585 | D28: ='S3 Concern summary'!C154 -> 8.2011679 | E28: ='S3 Concern summary'!D154 -> 0.24051343 | F28: ='S3 Concern summary'!E154 -> 26.047953 | G28: ='S3 Concern summary'!F154 -> 0.6549051 | H28: ='S3 Concern summary'!G154 -> 26.702858 | I28: ='S3 Concern summary'!H154 -> 0.31470223 | ... W28: ='S3 Concern summary'!V154 -> 0.35841247
B29: ='S3 Concern summary'!A164 -> KERALA | C29: ='S3 Concern summary'!B164 -> 7.5254755 | D29: ='S3 Concern summary'!C164 -> 1.9986655 | E29: ='S3 Concern summary'!D164 -> 0.26558661 | F29: ='S3 Concern summary'!E164 -> 5.5948303 | G29: ='S3 Concern summary'!F164 -> 0 | H29: ='S3 Concern summary'!G164 -> 5.5948303 | I29: ='S3 Concern summary'!H164 -> 0.037726958 | ... W29: ='S3 Concern summary'!V164 -> 0
B30: ='S3 Concern summary'!A168 -> TAMIL_NADU | C30: ='S3 Concern summary'!B168 -> 56.118213 | D30: ='S3 Concern summary'!C168 -> 10.639962 | E30: ='S3 Concern summary'!D168 -> 0.18959908 | F30: ='S3 Concern summary'!E168 -> 46.007785 | G30: ='S3 Concern summary'!F168 -> 5.6308968 | H30: ='S3 Concern summary'!G168 -> 51.638682 | I30: ='S3 Concern summary'!H168 -> 0.3125149 | ... W30: ='S3 Concern summary'!V168 -> 0.10241128
B31: ='S3 Concern summary'!A210 -> SOUTH_2 | C31: ='S3 Concern summary'!B210 -> 70.965573 | D31: ='S3 Concern summary'!C210 -> 24.011947 | E31: ='S3 Concern summary'!D210 -> 0.33836051 | F31: ='S3 Concern summary'!E210 -> 47.516077 | G31: ='S3 Concern summary'!F210 -> 2.6356283 | H31: ='S3 Concern summary'!G210 -> 50.151705 | I31: ='S3 Concern summary'!H210 -> 0.34285563 | ... W31: ='S3 Concern summary'!V210 -> 0.18867398
B32: ='S3 Concern summary'!A211 -> KARNATAKA | C32: ='S3 Concern summary'!B211 -> 37.594395 | D32: ='S3 Concern summary'!C211 -> 12.3509 | E32: ='S3 Concern summary'!D211 -> 0.32853036 | F32: ='S3 Concern summary'!E211 -> 25.540311 | G32: ='S3 Concern summary'!F211 -> 1.1722122 | H32: ='S3 Concern summary'!G211 -> 26.712523 | I32: ='S3 Concern summary'!H211 -> 0.30292547 | ... W32: ='S3 Concern summary'!V211 -> 0.50153808
B33: ='S3 Concern summary'!A248 -> TELANGANA | C33: ='S3 Concern summary'!B248 -> 33.371178 | D33: ='S3 Concern summary'!C248 -> 11.661047 | E33: ='S3 Concern summary'!D248 -> 0.34943469 | F33: ='S3 Concern summary'!E248 -> 21.975766 | G33: ='S3 Concern summary'!F248 -> 1.4634161 | H33: ='S3 Concern summary'!G248 -> 23.439182 | I33: ='S3 Concern summary'!H248 -> 0.38288314 | ... W33: ='S3 Concern summary'!V248 -> 0.0563003
B34: ='S3 Concern summary'!A270 -> WEST | C34: ='S3 Concern summary'!B270 -> 52.95458 | D34: ='S3 Concern summary'!C270 -> 23.533665 | E34: ='S3 Concern summary'!D270 -> 0.44441226 | F34: ='S3 Concern summary'!E270 -> 29.380119 | G34: ='S3 Concern summary'!F270 -> 3.2594435 | H34: ='S3 Concern summary'!G270 -> 32.639562 | I34: ='S3 Concern summary'!H270 -> 0.29802148 | ... W34: ='S3 Concern summary'!V270 -> 0.49151845
B35: ='S3 Concern summary'!A271 -> WEST_1 | C35: ='S3 Concern summary'!B271 -> 26.039414 | D35: ='S3 Concern summary'!C271 -> 13.490248 | E35: ='S3 Concern summary'!D271 -> 0.51807034 | F35: ='S3 Concern summary'!E271 -> 12.316887 | G35: ='S3 Concern summary'!F271 -> 1.0410209 | H35: ='S3 Concern summary'!G271 -> 13.357908 | I35: ='S3 Concern summary'!H271 -> 0.33968005 | ... W35: ='S3 Concern summary'!V271 -> 0.53597151
B36: ='S3 Concern summary'!A272 -> GUJARAT | C36: ='S3 Concern summary'!B272 -> 7.7923888 | D36: ='S3 Concern summary'!C272 -> 3.0522339 | E36: ='S3 Concern summary'!D272 -> 0.39169425 | F36: ='S3 Concern summary'!E272 -> 4.7960344 | G36: ='S3 Concern summary'!F272 -> 0.3029563 | H36: ='S3 Concern summary'!G272 -> 5.0989907 | I36: ='S3 Concern summary'!H272 -> 0.34099136 | ... W36: ='S3 Concern summary'!V272 -> -
B37: ='S3 Concern summary'!A292 -> MAHARASTRA | C37: ='S3 Concern summary'!B292 -> 18.247025 | D37: ='S3 Concern summary'!C292 -> 10.438014 | E37: ='S3 Concern summary'!D292 -> 0.57203923 | F37: ='S3 Concern summary'!E292 -> 7.5208529 | G37: ='S3 Concern summary'!F292 -> 0.73806458 | H37: ='S3 Concern summary'!G292 -> 8.2589175 | I37: ='S3 Concern summary'!H292 -> 0.33803106 | ... W37: ='S3 Concern summary'!V292 -> 0.53597151
B38: ='S3 Concern summary'!A312 -> WEST_2 | C38: ='S3 Concern summary'!B312 -> 26.915166 | D38: ='S3 Concern summary'!C312 -> 10.043417 | E38: ='S3 Concern summary'!D312 -> 0.37315083 | F38: ='S3 Concern summary'!E312 -> 17.063232 | G38: ='S3 Concern summary'!F312 -> 2.2184226 | H38: ='S3 Concern summary'!G312 -> 19.281654 | I38: ='S3 Concern summary'!H312 -> 0.25426744 | ... W38: ='S3 Concern summary'!V312 -> 0
B39: ='S3 Concern summary'!A313 -> GOA | C39: ='S3 Concern summary'!B313 -> 0 | D39: ='S3 Concern summary'!C313 -> 0 | E39: ='S3 Concern summary'!D313 -> - | F39: ='S3 Concern summary'!E313 -> 0 | G39: ='S3 Concern summary'!F313 -> 0 | H39: ='S3 Concern summary'!G313 -> 0 | I39: ='S3 Concern summary'!H313 -> 0 | ... W39: ='S3 Concern summary'!V313 -> -
B40: ='S3 Concern summary'!A317 -> MADHYA_PRADESH | C40: ='S3 Concern summary'!B317 -> 17.119879 | D40: ='S3 Concern summary'!C317 -> 4.5827594 | E40: ='S3 Concern summary'!D317 -> 0.26768644 | F40: ='S3 Concern summary'!E317 -> 12.681027 | G40: ='S3 Concern summary'!F317 -> 2.1131077 | H40: ='S3 Concern summary'!G317 -> 14.794134 | I40: ='S3 Concern summary'!H317 -> 0.27934143 | ... W40: ='S3 Concern summary'!V317 -> 0
B41: ='S3 Concern summary'!A327 -> MUMBAI | C41: ='S3 Concern summary'!B327 -> 9.7952869 | D41: ='S3 Concern summary'!C327 -> 5.4606572 | E41: ='S3 Concern summary'!D327 -> 0.55747803 | F41: ='S3 Concern summary'!E327 -> 4.382205 | G41: ='S3 Concern summary'!F327 -> 0.1053149 | H41: ='S3 Concern summary'!G327 -> 4.4875199 | I41: ='S3 Concern summary'!H327 -> 0.1299288 | ... W41: ='S3 Concern summary'!V327 -> -

Sheet Top Sheet
B5: S3 CONCERN SUMMARY | C5: TOTAL | F5: LAP | I5: SLAP
B6: Month | C6: 46174 | D6: 46143 | E6: 46113 | F6: 46174 | G6: 46143 | H6: 46113 | I6: 46174 | J6: 46143 | K6: 46113
B7: STOCK (OPENING + ADDITIONAL) | C7: 398.71142 | D7: 367.38386 | E7: 379.23343 | F7: 342.00708 | G7: 312.6786 | H7: 322.06548 | I7: 56.704344 | J7: 54.705267 | K7: 57.167943
B8: COLLECTED | C8: 111.14243 | D8: 103.46534 | E8: 76.850497 | F8: 95.820088 | G8: 87.821725 | H8: 66.146397 | I8: 15.322339 | J8: 15.643612 | K8: 10.7041
B9: Resolution % | C9: 0.27875406 | D9: 0.28162733 | E9: 0.20264695 | F9: 0.2801699 | G9: 0.280869 | H9: 0.20538183 | I9: 0.27021456 | J9: 0.28596171 | K9: 0.18723955
B10: Flow as on date | C10: 290.35865 | D10: 266.60587 | E10: 301.46391 | F10: 248.35302 | G10: 227.04099 | H10: 254.4254 | I10: 42.005638 | J10: 39.564886 | K10: 47.038514
B11: CLNPA | C11: 28.946237 | D11: 27.764001 | E11: 23.03847 | F11: 28.37597 | G11: 27.483941 | H11: 22.537507 | I11: 0.57026706 | J11: 0.28006004 | K11: 0.50096313
B12: Flow with CLNPA | C12: 319.30489 | D12: 294.36987 | E12: 324.50238 | F12: 276.72899 | G12: 254.52493 | H12: 276.96291 | I12: 42.575905 | J12: 39.844946 | K12: 47.539477
B13: Flow Projection- Commitment | C13: 69.721408 | D13: 51.153082 | E13: 67.59406 | F13: 60.422675 | G13: 39.031866 | H13: 55.036385 | I13: 9.2987328 | J13: 12.121216 | K13: 12.557675
B14: S3 Concern Actual Flow | C14: 319.30489 | D14: 294.36987 | E14: 324.50238 | F14: 276.72899 | G14: 254.52493 | H14: 276.96291 | I14: 42.575905 | J14: 39.844946 | K14: 47.539477
B15: Stage_3 Reduction -Projection | C15: 70.021246 | D15: 74.708779 | E15: 66.961314 | F15: 60.69425 | G15: 65.200873 | H15: 63.114548 | I15: 9.3269958 | J15: 9.5079053 | K15: 3.8467666
B16: S3 Reduction (GA Release +RB + Closure) - as on date | C16: 20.801828 | D16: 22.405462 | E16: 26.07653 | F16: 16.083773 | G16: 19.034914 | H16: 25.618848 | I16: 4.718055 | J16: 3.3705483 | K16: 0.45768205
B17: STAGE_3 ECL Release | C17: -5.694108 | D17: -7.2122609 | E17: -8.3576448
B18: S3 Concern Flow-EOM | C18: 319.30489 | D18: 76.666065 | E18: 103.93303 | F18: 276.72899 | G18: 59.890131 | H18: 82.144031 | I18: 42.575905 | J18: 16.775934 | K18: 21.789003
B19: S3 Reduction EOM | C19: 20.801828 | D19: 70.9551 | E19: 62.91124 | F19: 16.083773 | G19: 62.664363 | H19: 59.31089 | I19: 4.718055 | J19: 8.2907376 | K19: 3.6003491

Sheet Flow Data
A1: AGREEMENT NO | B1: Customer Name | C1: BRANCH | D1: NEW AREA | E1: SUB REGION | F1: MAIN REGION | G1: SUB-ZONE | H1: ZONE | I1: EMI | J1: Opening Adj OD+POS in crs | K1: GA May'26 (in Crs) | L1: Opening SLAB Ver_2 | M1: Opening DPD_Ver_1 | N1: Opening DPD_Ver_2 | O1: EOM DPD | P1: EOM SLAB | Q1: DPD As on Date | R1: CIF DPD EOM | S1: CIF | T1: May'26 ECL STAGE | U1: Jun'26 ECL STAGE | V1: GA in Crs Jun-26-Closing | W1: CIF GA | X1: 1st Payment Date (May|Apr|Mar|Feb|Jan|Dec) | Y1: Last Payment Date (May|Apr|Mar|Feb|Jan|Dec) | Z1: Banking (May|Apr|Mar|Feb|Jan|Dec) | AA1: DPD (May|Apr|Mar|Feb|Jan|Dec) | AB1: BKT FLAG | AC1: XFG
A2: HE01AHM00000010937 | B2: VINEETSINGH GULABSINGH RORE GULABSINGH | C2: AHMEDABAD ONE HE | D2: AHMEDABAD_1_AREA | E2: GUJARAT_1 | F2: GUJARAT | G2: WEST_1 | H2: WEST | I2: 160116 | J2: 1.3827706 | K2: 1.3947835 | L2: 60-89 | M2: 88 | N2: 88 | O2: 118 | P2: 90-180 | Q2: 107 | R2: 118 | S2: 314273 | T2: STAGE_2B | U2: STAGE_3 | V2: 1.4103326 | W2: 2.2924086 | X2: 27 | 22 | 21 | 28 | 5 | 0 | Y2: 27 | 22 | 21 | 28 | 5 | 0 | Z2: 0 | 0 | 0 | 0 | 0 | 0 | AA2: 88 | 85 | 86 | 86 | 88 | 88 | AB2: Existing Stock | AC2: -
A3: X0HEAHM00003226232 | B3: VINEET GULABSINGH RORE | C3: AHMEDABAD ONE HE | D3: AHMEDABAD_1_AREA | E3: GUJARAT_1 | F3: GUJARAT | G3: WEST_1 | H3: WEST | I3: 113660 | J3: 0.8635743 | K3: 0.8716418 | L3: 60-89 | M3: 88 | N3: 88 | O3: 118 | P3: 90-180 | Q3: 107 | R3: 118 | S3: 314273 | T3: STAGE_2B | U3: STAGE_3 | V3: 0.882076 | W3: 2.2924086 | X3: 27 | 22 | 21 | 28 | 5 | 0 | Y3: 27 | 22 | 21 | 28 | 5 | 0 | Z3: 0 | 0 | 0 | 0 | 0 | 0 | AA3: 88 | 85 | 86 | 86 | 88 | 88 | AB3: Existing Stock | AC3: -
A4: X0HERHE00001794859 | B4: NARESH NATHUBHAI VORA | C4: SURAT ONE HE | D4: SURAT_1_AREA | E4: GUJARAT_2 | F4: GUJARAT | G4: WEST_1 | H4: WEST | I4: 58098 | J4: 0.47624289 | K4: 0.48033879 | L4: 60-89 | M4: 88 | N4: 88 | O4: 118 | P4: 90-180 | Q4: 107 | R4: 118 | S4: 2619083 | T4: STAGE_2A | U4: STAGE_3 | V4: 0.48563709 | W4: 0.78859339 | X4: 0 | 0 | 0 | 27 | 31 | 31 | Y4: 0 | 0 | 0 | 27 | 31 | 31 | Z4: 0 | 0 | 0 | 0 | 0 | 0 | AA4: 88 | 57 | 27 | 0 | 0 | 0 | AB4: Direct Flow | AC4: -
A5: HE01RHE00000044665 | B5: JAYESH DHIRAJLAL GANDHI DHIRAJLAL | C5: SURAT ONE HE | D5: SURAT_1_AREA | E5: GUJARAT_2 | F5: GUJARAT | G5: WEST_1 | H5: WEST | I5: 96608 | J5: 0.5771461 | K5: 0.5822201 | L5: 60-89 | M5: 88 | N5: 88 | O5: 118 | P5: 90-180 | Q5: 107 | R5: 118 | S5: 11949646 | T5: STAGE_2A | U5: STAGE_3 | V5: 0.5887569 | W5: 0.5887569 | X5: 0 | 0 | 0 | 24 | 30 | 24 | Y5: 0 | 0 | 0 | 24 | 30 | 24 | Z5: 0 | 0 | 0 | 0 | 0 | 0 | AA5: 88 | 57 | 27 | 0 | 0 | 0 | AB5: Direct Flow | AC5: -
A6: ML01ZUA00000090164 | B6: NARESHKUMAR PRATAPRAY MODI PRATAPBHAI | C6: BOTAD HE | D6: SAURASHTRA_2_AREA | E6: GUJARAT_3 | F6: GUJARAT | G6: WEST_1 | H6: WEST | I6: 50450 | J6: 0.2999348 | K6: 0.3036556 | L6: 60-89 | M6: 88 | N6: 88 | O6: 118 | P6: 90-180 | Q6: 107 | R6: 118 | S6: 17316533 | T6: STAGE_2B | U6: STAGE_3 | V6: 0.3084672 | W6: 0.3084672 | X6: 30 | 0 | 31 | 28 | 0 | 0 | Y6: 31 | 0 | 31 | 28 | 0 | 0 | Z6: 0 | 0 | 0 | 0 | 0 | 0 | AA6: 88 | 85 | 55 | 55 | 58 | 27 | AB6: Existing Stock | AC6: -
A7: HE01RTH00000023767 | B7: HIMATBHAI BHAYABHAI CHHAYANI BHAYABHAI | C7: RAJKOT ONE HE | D7: SAURASHTRA_1_AREA | E7: GUJARAT_3 | F7: GUJARAT | G7: WEST_1 | H7: WEST | I7: 31825 | J7: 0.2747347 | K7: 0.27724 | L7: 60-89 | M7: 88 | N7: 88 | O7: 118 | P7: 90-180 | Q7: 107 | R7: 118 | S7: 9579422 | T7: STAGE_2A | U7: STAGE_3 | V7: 0.2804843 | W7: 0.2804843 | X7: 0 | 27 | 0 | 11 | 0 | 0 | Y7: 0 | 27 | 0 | 11 | 0 | 0 | Z7: 0 | 0 | 0 | REP | REP | 5TH | AA7: 88 | 57 | 55 | 24 | 58 | 57 | AB7: Last Month Flow | AC7: -
A8: X0HEMBI00003446593 | B8: CHANDRESHBHAI A VASA | C8: MORBI HE | D8: SAURASHTRA_1_AREA | E8: GUJARAT_3 | F8: GUJARAT | G8: WEST_1 | H8: WEST | I8: 21728 | J8: 0.1532134 | K8: 0.15473004 | L8: 60-89 | M8: 88 | N8: 88 | O8: 118 | P8: 90-180 | Q8: 107 | R8: 118 | S8: 8367148 | T8: STAGE_2B | U8: STAGE_3 | V8: 0.1566909 | W8: 0.1566909 | X8: 26 | 27 | 25 | 25 | 24 | 26 | Y8: 26 | 27 | 25 | 25 | 24 | 26 | Z8: 0 | 0 | 0 | 0 | 0 | 0 | AA8: 88 | 85 | 86 | 86 | 88 | 88 | AB8: Existing Stock | AC8: -
A9: ML01MMG00000046588 | B9: HARSHA SAILESHBHAI BHANDARI BHAGWANBHAI | C9: VALSAD HE | D9: VAPI_AREA | E9: GUJARAT_2 | F9: GUJARAT | G9: WEST_1 | H9: WEST | I9: 26802 | J9: 0.1454798 | K9: 0.1471181 | L9: 60-89 | M9: 88 | N9: 88 | O9: 118 | P9: 90-180 | Q9: 107 | R9: 118 | S9: 12173170 | T9: STAGE_2A | U9: STAGE_3 | V9: 0.1487309 | W9: 0.1487309 | X9: 0 | 30 | 31 | 28 | 31 | 31 | Y9: 0 | 30 | 31 | 28 | 31 | 31 | Z9: 0 | 0 | 0 | 0 | 0 | 0 | AA9: 88 | 57 | 55 | 55 | 58 | 57 | AB9: Last Month Flow | AC9: -
A10: HE01LOS00000064119 | B10: ATUL MAHESH THAKUR Mahesh Thakur | C10: SILVASSA HE | D10: VAPI_AREA | E10: GUJARAT_2 | F10: GUJARAT | G10: WEST_1 | H10: WEST | I10: 14916 | J10: 0.110627 | K10: 0.1117058 | L10: 60-89 | M10: 88 | N10: 88 | O10: 118 | P10: 90-180 | Q10: 107 | R10: 118 | S10: 14157335 | T10: STAGE_2B | U10: STAGE_3 | V10: 0.1131012 | W10: 0.1131012 | X10: 0 | 17 | 0 | 0 | 0 | 31 | Y10: 0 | 17 | 0 | 0 | 0 | 31 | Z10: 0 | 0 | 0 | 0 | 0 | 0 | AA10: 88 | 57 | 86 | 55 | 27 | 0 | AB10: Last Month Flow | AC10: -
A11: X0HERUC00003440139 | B11: NOMAN SHAMSUDDIN SHAIKH | C11: BHARUCH HE | D11: SURAT_2_AREA | E11: GUJARAT_5 | F11: GUJARAT | G11: WEST_1 | H11: WEST | I11: 17747 | J11: 0.0932526 | K11: 0.094274251 | L11: 60-89 | M11: 88 | N11: 88 | O11: 118 | P11: 90-180 | Q11: 107 | R11: 118 | S11: 6935968 | T11: STAGE_2B | U11: STAGE_3 | V11: 0.0947236 | W11: 0.0947236 | X11: 14 | 7 | 13 | 6 | 6 | 29 | Y11: 21 | 7 | 13 | 6 | 6 | 29 | Z11: 0 | 0 | 0 | 0 | 0 | 0 | AA11: 88 | 85 | 86 | 86 | 88 | 88 | AB11: Existing Stock | AC11: -
A12: ML01MEH00000065812 | B12: AJAYKUMAR KASHIRAMBHAI PATEL KASHIRAMBHAI | C12: MEHSANA HE | D12: NORTH_GUJARAT_AREA | E12: GUJARAT_1 | F12: GUJARAT | G12: WEST_1 | H12: WEST | I12: 15416 | J12: 0.0791049 | K12: 0.0800239 | L12: 60-89 | M12: 88 | N12: 88 | O12: 118 | P12: 90-180 | Q12: 107 | R12: 118 | S12: 14562461 | T12: STAGE_2A | U12: STAGE_3 | V12: 0.0812082 | W12: 0.0812082 | X12: 0 | 0 | 13 | 19 | 0 | 0 | Y12: 0 | 0 | 13 | 19 | 0 | 0 | Z12: 0 | 0 | 0 | 0 | 0 | 0 | AA12: 88 | 57 | 27 | 24 | 27 | 0 | AB12: Last Month Flow | AC12: -
A13: ML01ZUA00000086166 | B13: KANJIBHAI DHUDABHAI VAGHELA DHUDABHAI | C13: BOTAD HE | D13: SAURASHTRA_2_AREA | E13: GUJARAT_3 | F13: GUJARAT | G13: WEST_1 | H13: WEST | I13: 12613 | J13: 0.0688967 | K13: 0.0697473 | L13: 60-89 | M13: 88 | N13: 88 | O13: 118 | P13: 90-180 | Q13: 107 | R13: 118 | S13: 16809827 | T13: STAGE_2A | U13: STAGE_3 | V13: 0.0708457 | W13: 0.0708457 | X13: 0 | 0 | 0 | 23 | 12 | 9 | Y13: 0 | 0 | 0 | 23 | 12 | 9 | Z13: 0 | 0 | 0 | 0 | 0 | 0 | AA13: 88 | 57 | 27 | 0 | 0 | 0 | AB13: Direct Flow | AC13: -
... A771: HE01RHT00000043180 | B771: LAKHYAHIRA GOGOI JITUL GOGOI | C771: JORHAT HE | D771: JORHAT_AREA | E771: NE_REGION | F771: NORTH_EAST | G771: EAST_2 | H771: EAST | I771: 39949 | J771: 0.2761478 | K771: 0.02785836 | L771: 60-89 | M771: 88 | N771: 88 | O771: 118 | P771: 90-180 | Q771: 107 | R771: 118 | S771: 11930938 | T771: STAGE_2B | U771: STAGE_3 | V771: 0.02817286 | W771: 0.02817286 | X771: 27 | 22 | 2 | 0 | 28 | 17 | Y771: 27 | 23 | 11 | 0 | 28 | 17 | Z771: 0 | 0 | 0 | 0 | 0 | 0 | AA771: 88 | 85 | 86 | 86 | 58 | 57 | AB771: Existing Stock | AC771: -
